X byte sent!
Files sent!
X byte sent!
Converting image: 0.png
Archiving file: 0.png
Sending file: 0.jpg
Waiting for X byte...
2900
Waiting for X byte...
fileNameLen
Waiting for X byte...
fileName
Waiting for X byte...
File sent
Archiving file: 0.jpg
Converting image: 1.png
Archiving file: 1.png
Sending file: 1.jpg
Waiting for X byte...
3332
Waiting for X byte...
fileNameLen
Waiting for X byte...
fileName
Waiting for X byte...
File sent
Archiving file: 1.jpg
Converting image: 2.png
Archiving file: 2.png
Sending file: 2.jpg
Waiting for X byte...
3220
Waiting for X byte...
fileNameLen
Waiting for X byte...
Traceback (most recent call last):
  File "/usr/lib/python3/dist-packages/serial/serialposix.py", line 501, in read
    'device reports readiness to read but returned no data '
serial.serialutil.SerialException: device reports readiness to read but returned no data (device disconnected or multiple access on port?)

During handling of the above exception, another exception occurred:

Traceback (most recent call last):
  File "/home/pi/Documents/OTIS-2U-Repo/main.py", line 88, in <module>
    XBee_sat.send_files()
  File "/home/pi/Documents/OTIS-2U-Repo/XBee_sat.py", line 40, in send_files
    collectFiles('/home/pi/Documents/OTIS-2U-Repo/images/', '/home/pi/Documents/OTIS-2U-Repo/archived/')
  File "/home/pi/Documents/OTIS-2U-Repo/XBee_sat.py", line 35, in collectFiles
    satellite.send_file(mydir, fileName)
  File "/home/pi/Documents/OTIS-2U-Repo/XBee_class.py", line 57, in send_file
    self.wait_file_sync()
  File "/home/pi/Documents/OTIS-2U-Repo/XBee_class.py", line 33, in wait_file_sync
    rec = self.ser.read()
  File "/usr/lib/python3/dist-packages/serial/serialposix.py", line 509, in read
    raise SerialException('read failed: {}'.format(e))
serial.serialutil.SerialException: read failed: device reports readiness to read but returned no data (device disconnected or multiple access on port?)
